<?xml version="1.0" encoding="UTF-8"?>
<testng-results skipped="0" failed="2" total="5" passed="3">
  <reporter-output>
  </reporter-output>
  <suite name="Suite" duration-ms="8286" started-at="2017-09-13T20:01:35Z" finished-at="2017-09-13T20:01:43Z">
    <groups>
    </groups>
    <test name="Test" duration-ms="8286" started-at="2017-09-13T20:01:35Z" finished-at="2017-09-13T20:01:43Z">
      <class name="TestAssertions">
        <test-method status="FAIL" signature="test3()[pri:0, instance:TestAssertions@282ba1e]" name="test3" duration-ms="0" started-at="2017-09-13T16:01:43Z" finished-at="2017-09-13T16:01:43Z">
          <exception class="java.lang.AssertionError">
            <message>
              <![CDATA[expected [true] but found [false]]]>
            </message>
            <full-stacktrace>
              <![CDATA[java.lang.AssertionError: expected [true] but found [false]
	at org.testng.Assert.fail(Assert.java:94)
	at org.testng.Assert.failNotEquals(Assert.java:494)
	at org.testng.Assert.assertTrue(Assert.java:42)
	at org.testng.Assert.assertTrue(Assert.java:52)
	at TestAssertions.test3(TestAssertions.java:35)
	at sun.reflect.NativeMethodAccessorImpl.invoke0(Native Method)
	at sun.reflect.NativeMethodAccessorImpl.invoke(Unknown Source)
	at sun.reflect.DelegatingMethodAccessorImpl.invoke(Unknown Source)
	at java.lang.reflect.Method.invoke(Unknown Source)
	at org.testng.internal.MethodInvocationHelper.invokeMethod(MethodInvocationHelper.java:80)
	at org.testng.internal.Invoker.invokeMethod(Invoker.java:714)
	at org.testng.internal.Invoker.invokeTestMethod(Invoker.java:901)
	at org.testng.internal.Invoker.invokeTestMethods(Invoker.java:1231)
	at org.testng.internal.TestMethodWorker.invokeTestMethods(TestMethodWorker.java:127)
	at org.testng.internal.TestMethodWorker.run(TestMethodWorker.java:111)
	at org.testng.TestRunner.privateRun(TestRunner.java:767)
	at org.testng.TestRunner.run(TestRunner.java:617)
	at org.testng.SuiteRunner.runTest(SuiteRunner.java:334)
	at org.testng.SuiteRunner.runSequentially(SuiteRunner.java:329)
	at org.testng.SuiteRunner.privateRun(SuiteRunner.java:291)
	at org.testng.SuiteRunner.run(SuiteRunner.java:240)
	at org.testng.SuiteRunnerWorker.runSuite(SuiteRunnerWorker.java:52)
	at org.testng.SuiteRunnerWorker.run(SuiteRunnerWorker.java:86)
	at org.testng.TestNG.runSuitesSequentially(TestNG.java:1198)
	at org.testng.TestNG.runSuitesLocally(TestNG.java:1123)
	at org.testng.TestNG.run(TestNG.java:1031)
	at org.testng.TestNG.privateMain(TestNG.java:1338)
	at org.testng.TestNG.main(TestNG.java:1307)
]]>
            </full-stacktrace>
          </exception> <!-- java.lang.AssertionError -->
          <reporter-output>
          </reporter-output>
        </test-method> <!-- test3 -->
        <test-method status="PASS" signature="test2()[pri:0, instance:TestAssertions@282ba1e]" name="test2" duration-ms="0" started-at="2017-09-13T16:01:43Z" finished-at="2017-09-13T16:01:43Z">
          <reporter-output>
          </reporter-output>
        </test-method> <!-- test2 -->
        <test-method status="FAIL" signature="test1()[pri:0, instance:TestAssertions@282ba1e]" name="test1" duration-ms="0" started-at="2017-09-13T16:01:43Z" finished-at="2017-09-13T16:01:43Z">
          <exception class="java.lang.AssertionError">
            <message>
              <![CDATA[Test 1 has failed]]>
            </message>
            <full-stacktrace>
              <![CDATA[java.lang.AssertionError: Test 1 has failed
	at org.testng.Assert.fail(Assert.java:94)
	at TestAssertions.test1(TestAssertions.java:18)
	at sun.reflect.NativeMethodAccessorImpl.invoke0(Native Method)
	at sun.reflect.NativeMethodAccessorImpl.invoke(Unknown Source)
	at sun.reflect.DelegatingMethodAccessorImpl.invoke(Unknown Source)
	at java.lang.reflect.Method.invoke(Unknown Source)
	at org.testng.internal.MethodInvocationHelper.invokeMethod(MethodInvocationHelper.java:80)
	at org.testng.internal.Invoker.invokeMethod(Invoker.java:714)
	at org.testng.internal.Invoker.invokeTestMethod(Invoker.java:901)
	at org.testng.internal.Invoker.invokeTestMethods(Invoker.java:1231)
	at org.testng.internal.TestMethodWorker.invokeTestMethods(TestMethodWorker.java:127)
	at org.testng.internal.TestMethodWorker.run(TestMethodWorker.java:111)
	at org.testng.TestRunner.privateRun(TestRunner.java:767)
	at org.testng.TestRunner.run(TestRunner.java:617)
	at org.testng.SuiteRunner.runTest(SuiteRunner.java:334)
	at org.testng.SuiteRunner.runSequentially(SuiteRunner.java:329)
	at org.testng.SuiteRunner.privateRun(SuiteRunner.java:291)
	at org.testng.SuiteRunner.run(SuiteRunner.java:240)
	at org.testng.SuiteRunnerWorker.runSuite(SuiteRunnerWorker.java:52)
	at org.testng.SuiteRunnerWorker.run(SuiteRunnerWorker.java:86)
	at org.testng.TestNG.runSuitesSequentially(TestNG.java:1198)
	at org.testng.TestNG.runSuitesLocally(TestNG.java:1123)
	at org.testng.TestNG.run(TestNG.java:1031)
	at org.testng.TestNG.privateMain(TestNG.java:1338)
	at org.testng.TestNG.main(TestNG.java:1307)
]]>
            </full-stacktrace>
          </exception> <!-- java.lang.AssertionError -->
          <reporter-output>
          </reporter-output>
        </test-method> <!-- test1 -->
      </class> <!-- TestAssertions -->
      <class name="TestSysoutFail">
        <test-method status="PASS" signature="f()[pri:0, instance:TestSysoutFail@50675690]" name="f" duration-ms="4099" started-at="2017-09-13T16:01:35Z" finished-at="2017-09-13T16:01:39Z">
          <reporter-output>
          </reporter-output>
        </test-method> <!-- f -->
      </class> <!-- TestSysoutFail -->
      <class name="TestGoogleSearch">
        <test-method status="PASS" signature="f()[pri:0, instance:TestGoogleSearch@13b6d03]" name="f" duration-ms="4185" started-at="2017-09-13T16:01:39Z" finished-at="2017-09-13T16:01:43Z">
          <reporter-output>
          </reporter-output>
        </test-method> <!-- f -->
      </class> <!-- TestGoogleSearch -->
    </test> <!-- Test -->
  </suite> <!-- Suite -->
</testng-results>
